Workbook

Sheet INVENTARIO
A1: CÓDIGO PRODUCTO | B1: DESCRIPCIÓN | C1: EXISTENCIAS | D1: PRECIO | E1: SUMA
A2: MONP0410 | B2: ALFOMBRA PISO NPR | C2: 2 | D2: 80 | E2: =(INVENTARIO!$D2*INVENTARIO!$C2) -> 160
A3: MONP0399 | B3: ALFOMBRA PISO SUPER DUTY | C3: 0 | D3: 90 | E3: =(INVENTARIO!$D3*INVENTARIO!$C3) -> 0
A4: MONP0409 | B4: ALFOMBRA PISO TRITON | C4: 2 | D4: 80 | E4: =(INVENTARIO!$D4*INVENTARIO!$C4) -> 160
A5: MONP0030 | B5: ALTERNADOR FVR 24V 50 AMPERIOS | C5: 1 | D5: 350 | E5: =(INVENTARIO!$D5*INVENTARIO!$C5) -> 350
A6: MONP0211 | B6: ALTERNADOR GAMMA NPR 24V 80 AMPERIOS | C6: 1 | D6: 350 | E6: =(INVENTARIO!$D6*INVENTARIO!$C6) -> 350
A7: MONP0376 | B7: ALTERNADOR NPR 12V GAMMA 60 AMPERIOS NKR/NHR | C7: 1 | D7: 230 | E7: =(INVENTARIO!$D7*INVENTARIO!$C7) -> 230
A8: MONP0059 | B8: ALTERNADOR NPR 12V. GAMMA 80 AMPERIOS | C8: 2 | D8: 320 | E8: =(INVENTARIO!$D8*INVENTARIO!$C8) -> 640
A9: MONP0060 | B9: ALTERNADOR NPR 24V.GAMMA 45 AMPERIOS | C9: 1 | D9: 240 | E9: =(INVENTARIO!$D9*INVENTARIO!$C9) -> 240
A10: MONP0488 | B10: AMORTIGUADOR DEL FVR | C10: 2 | D10: 140 | E10: =(INVENTARIO!$D10*INVENTARIO!$C10) -> 280
A11: MONP0477 | B11: AMORTIGUADOR DELANTERO CARGO 1721 (125$ C/U) | C11: 2 | D11: 125 | E11: =(INVENTARIO!$D11*INVENTARIO!$C11) -> 250
A12: MONP0267 | B12: AMORTIGUADOR DELANTERO NPR, SUPER DUTY, FORTUNER MONROE | C12: 4 | D12: 65 | E12: =(INVENTARIO!$D12*INVENTARIO!$C12) -> 260
A13: MONP0493 | B13: AMORTIGUADOR TRASERO CARGO 1721 (125$ C/U) | C13: 2 | D13: 125 | E13: =(INVENTARIO!$D13*INVENTARIO!$C13) -> 250
... A222: MONP0156 | B222: FAROS LED CUADRADO, UNIVERSAL 12V | C222: 0 | D222: 100 | E222: =(INVENTARIO!$D222*INVENTARIO!$C222) -> 0
A223: MONP0145 | B223: FILTRO | C223: 4 | E223: =(INVENTARIO!$D223*INVENTARIO!$C223) -> 0
A224: MONP0135 | B224: FILTRO ACEITE CARGO 1721 | C224: 1 | D224: 40 | E224: =(INVENTARIO!$D224*INVENTARIO!$C224) -> 40
A225: MONP0133 | B225: FILTRO ACEITE CARGO 815 | C225: 1 | D225: 18 | E225: =(INVENTARIO!$D225*INVENTARIO!$C225) -> 18
A226: MONP0136 | B226: FILTRO ACEITE KODIAT | C226: 4 | D226: 25 | E226: =(INVENTARIO!$D226*INVENTARIO!$C226) -> 100
A227: MONP0370 | B227: FILTRO ACEITE NKR/NHR | C227: 5 | D227: 10 | E227: =(INVENTARIO!$D227*INVENTARIO!$C227) -> 50
A228: MONP0132 | B228: FILTRO ACEITE NPR | C228: 26 | D228: 15 | E228: =(INVENTARIO!$D228*INVENTARIO!$C228) -> 390
A229: MONP0490 | B229: FILTRO AIRE 6BD1 | C229: 4 | D229: 30 | E229: =(INVENTARIO!$D229*INVENTARIO!$C229) -> 120
A230: MONP0139 | B230: FILTRO AIRE CARGO 1721 | C230: 3 | D230: 40 | E230: =(INVENTARIO!$D230*INVENTARIO!$C230) -> 120
A231: MONP0140 | B231: FILTRO AIRE CARGO 815 | C231: 3 | D231: 28 | E231: =(INVENTARIO!$D231*INVENTARIO!$C231) -> 84
A232: MONP0141 | B232: FILTRO AIRE FVR CON TURBO | C232: 2 | D232: 45 | E232: =(INVENTARIO!$D232*INVENTARIO!$C232) -> 90
A233: MONP0142 | B233: FILTRO AIRE NPR 4HF1 SIN TURBO/NKR/NHR | C233: 3 | D233: 25 | E233: =(INVENTARIO!$D233*INVENTARIO!$C233) -> 75
A234: MONP0143 | B234: FILTRO AIRE NPR 4HG1 CON TURBO | C234: 5 | D234: 35 | E234: =(INVENTARIO!$D234*INVENTARIO!$C234) -> 175
A235: MONP0131 | B235: FILTRO GASOIL ALTOS GEMELOS ELENFIL/IFL/GENERICOS | C235: 81 | D235: 8 | E235: =(INVENTARIO!$D235*INVENTARIO!$C235) -> 648
... A292: MONP0236 | B292: KIT EMPACADURAS NKR | C292: 1 | D292: 70 | E292: =(INVENTARIO!$D292*INVENTARIO!$C292) -> 70
A293: MONP0138 | B293: KIT FILTRO ACEDELCO | D293: 60 | E293: =(INVENTARIO!$D293*INVENTARIO!$C293) -> 0
A294: MONP0137 | B294: KIT FILTRO PARTMO FILTOR LARGO | C294: 0 | D294: 70 | E294: =(INVENTARIO!$D294*INVENTARIO!$C294) -> 0
A295: MONP0381 | B295: KIT LAINAS AJUSTES SATELITES Y PLANETARIOS NPR AJUSTE TRASMISION | C295: 2 | D295: 30 | E295: =(INVENTARIO!$D295*INVENTARIO!$C295) -> 60
A296: MONP0382 | B296: KIT LAINAS AJUSTES SATELITES Y PLANETARIOS NPR MODELO VIEJO | C296: 4 | D296: 20 | E296: =(INVENTARIO!$D296*INVENTARIO!$C296) -> 80
A297: MONP0405 | B297: KIT PEDAL EMBRAGUE NPR/NKR | C297: 9 | D297: 20 | E297: =(INVENTARIO!$D297*INVENTARIO!$C297) -> 180
A298: MONP0462 | B298: KIT REPARACION VALVULA 4 VIAS | C298: 1 | D298: 25 | E298: =(INVENTARIO!$D298*INVENTARIO!$C298) -> 25
A299: MONP0430 | B299: KIT SATELITES Y PLANETARIO NPR CON TURBO 4HG1 | C299: 1 | D299: 160 | E299: =(INVENTARIO!$D299*INVENTARIO!$C299) -> 160
A300: MONP0432 | B300: KIT SATELITES Y PLANETARIO NPR SIN TURBO 4HF1 | C300: 1 | D300: 110 | E300: =(INVENTARIO!$D300*INVENTARIO!$C300) -> 110
A301: MONP0371 | B301: KIT SERPENTIN ENFRIAMIENTO ACEITE | C301: 4 | D301: 22 | E301: =(INVENTARIO!$D301*INVENTARIO!$C301) -> 88
A302: MONP0369 | B302: KIT YUGO ESPIGA Y BOTELLA NPR SPICER | C302: 1 | D302: 220 | E302: =(INVENTARIO!$D302*INVENTARIO!$C302) -> 220
A303: MONP0172 | B303: LATERAL 12V | C303: 30 | D303: 7 | E303: =(INVENTARIO!$D303*INVENTARIO!$C303) -> 210
A304: MONP0173 | B304: LATERAL24V | C304: 33 | D304: 7 | E304: =(INVENTARIO!$D304*INVENTARIO!$C304) -> 231
...
